<?xml version="1.0"?>
<robot xmlns:xacro="http://www.ros.org/wiki/xacro">

    <xacro:include filename="inertial_macros.xacro"/>
    
    <material name="white">
        <color rgba="1 1 1 1"/>
    </material>

    <material name="orange">
        <color rgba="1 0.3 0.1 1"/>
    </material>

    <material name="blue">
        <color rgba="0.2 0.2 1 1"/>
    </material>

    <material name="black">
        <color rgba="0 0 0 1"/>
    </material>

    <link name="base_link">
        
    </link>

    <joint name="base_footprint_joint" type="fixed">
        <parent link="base_link"/>
        <child link="base_footprint"/>
        <origin xyz="0.0 0.0 0.0" rpy="0.0 0.0 0.0"/>
    </joint>

    <link name="base_footprint">
        
    </link>

    <joint name="chassis_joint" type="fixed">
        <parent link="base_link"/>
        <child link="chassis"/>
        <origin xyz="-0.08 0.0 0.0" rpy="0.0 0.0 0.0"/>
        
    </joint>

    <link name="chassis">
        <visual>
            <origin xyz="0.15 0.0 0.02"/>
            
            <geometry>
                <cylinder radius="0.17" length="0.06"/>
            </geometry>
            <material name="white"></material>
        </visual>
        <collision>
            <origin xyz="0.15 0.0 0.01"/>
            
            <geometry>
                <cylinder radius="0.17" length="0.06"/>
            </geometry>
        </collision>
        <xacro:inertial_cylinder mass="1" radius="0.17" length="0.06">
            <origin xyz="0.15 0.0 0.01" rpy="0.0 0.0 0.0"/>
        </xacro:inertial_cylinder>
    </link>

    <gazebo reference="chassis">
        <material>Gazebo/White</material>
    </gazebo>

    <joint name="left_wheel_joint" type="continuous">
        <parent link="base_link"/>
        <child link="left_wheel"/>
        <origin xyz="0.0 0.11 0.0" rpy="-${pi/2} 0.0 0.0"/>
        <axis xyz="0.0 0.0 1"/>
    </joint>

    <link name="left_wheel">
        <visual>
            <geometry>
                <cylinder radius="0.022" length="0.02"/>
            </geometry>
            <material name="blue"></material>
        </visual>
        <collision>
            <geometry>
                <cylinder radius="0.03" length="0.02"/>
            </geometry>
        </collision>
        <xacro:inertial_cylinder mass="0.1" radius="0.022" length="0.02">
            <origin xyz="0.0 0.0 0.0" rpy="0.0 0.0 0.0"/>
        </xacro:inertial_cylinder>
    </link>

    <gazebo reference="left_wheel">
        <material>Gazebo/Blue</material>
    </gazebo>

    <joint name="right_wheel_joint" type="continuous">
        <parent link="base_link"/>
        <child link="right_wheel"/>
        <origin xyz="0.0 -0.11 0.0" rpy="${pi/2} 0.0 0.0"/>
        <axis xyz="0.0 0.0 -1"/>
    </joint>

    <link name="right_wheel">
        <visual>
            <geometry>
                <cylinder radius="0.022" length="0.02"/>
            </geometry>
            <material name="blue"></material>
        </visual>
        <collision>
            <geometry>
                <cylinder radius="0.022" length="0.02"/>
            </geometry>
        </collision>
        <xacro:inertial_cylinder mass="0.1" radius="0.03" length="0.04">
            <origin xyz="0.0 0.0 0.0" rpy="0.0 0.0 0.0"/>
        </xacro:inertial_cylinder>
    </link>

    <gazebo reference="right_wheel">
        <material>Gazebo/Blue</material>
    </gazebo>

    <joint name="caster_wheel" type="fixed">
        <parent link="chassis"/>
        <child link="caster_wheel"/>
        <origin xyz="0.27 0.0 -0.01" rpy="0.0 0.0 0.0"/>
    </joint>

    <link name="caster_wheel">
        <visual>
            <geometry>
                <sphere radius="0.01"/>
            </geometry>
            <material name="black"></material>
        </visual>
        <collision>
            <geometry>
                <sphere radius="0.01"/>
            </geometry>
        </collision>
        <xacro:inertial_sphere mass="0.1" radius="0.01">
            <origin xyz="0.0 0.0 0.0" rpy="0.0 0.0 0.0"/>
        </xacro:inertial_sphere>
    </link>

    <gazebo reference="caster_wheel">
        <material>Gazebo/Black</material>
        <mu1 value="0.001"></mu1>
        <mu2 value="0.001"></mu2>
    </gazebo>

</robot>